File: force-displacement.csv
Results Table 1
,Specimen label,Width,Thickness,Length,Tensile strain (Displacement) at Break (Standard),Maximum Tensile stress
,,(mm),(mm),(mm),(%),(MPa)
"1","BrassS4_01","12.73","1.52","78.49","34.28","427.03"

1,Time,Displacement,Force
,(s),(mm),(N)
"","0.0000","0.0000","39.3799"
"","0.1000","0.0042","43.7967"
"","0.2000","0.0175","45.0747"
"","0.3000","0.0481","45.3055"
"","0.4000","0.0677","45.9245"
"","0.5000","0.0893","46.4365"
"","0.6000","0.1101","46.8672"
"","0.7000","0.1312","47.7023"
"","0.8000","0.1532","48.9681"
"","0.9000","0.1733","50.2050"
"","1.0000","0.1951","57.3266"
"","1.1000","0.2153","61.1670"
"","1.2000","0.2376","122.5777"
"","1.3000","0.2583","352.3291"
"","1.3930","0.2779","603.4550"
"","1.4850","0.2975","853.6439"
"","1.5850","0.3181","1101.6654"
"","1.6850","0.3403","1320.4095"
"","1.7850","0.3607","1486.0929"
"","1.8850","0.3822","1693.8580"
"","1.9850","0.4030","1889.6278"
"","2.0850","0.4242","2092.7607"
"","2.1850","0.4460","2295.0400"
"","2.2850","0.4665","2482.3716"
"","2.3850","0.4878","2675.9993"
"","2.4850","0.5085","2857.5986"
"","2.5850","0.5306","3047.4729"
"","2.6850","0.5512","3215.5198"
"","2.7850","0.5726","3395.0940"
"","2.8850","0.5934","3558.3235"
"","2.9850","0.6147","3726.4924"
"","3.0850","0.6366","3895.9243"
"","3.1850","0.6568","4045.8950"
"","3.2850","0.6786","4210.0874"
"","3.3850","0.6991","4356.4507"
"","3.4850","0.7211","4516.4858"
"","3.5850","0.7418","4652.4258"
"","3.6850","0.7631","4794.0342"
"","3.7850","0.7840","4920.6689"
"","3.8850","0.8050","5049.5439"
"","3.9850","0.8271","5180.7729"
"","4.0850","0.8473","5292.5933"
"","4.1850","0.8692","5416.3809"
"","4.2850","0.8898","5524.3525"
"","4.3850","0.9113","5638.0566"
"","4.4850","0.9328","5742.7349"
"","4.5850","0.9535","5843.6226"
"","4.6850","0.9749","5939.2856"
"","4.7850","0.9955","6030.7437"
"","4.8850","1.0177","6123.7974"
"","4.9850","1.0379","6199.6689"
"","5.0850","1.0595","6283.8262"
"","5.1850","1.0802","6354.6665"
"","5.2850","1.1016","6428.6841"
"","5.3850","1.1235","6494.5205"
"","5.4850","1.1437","6555.3330"
"","5.5850","1.1654","6613.3672"
"","5.6850","1.1857","6664.8760"
"","5.7850","1.2081","6719.6392"
"","5.8850","1.2286","6761.3931"
"","5.9850","1.2502","6809.8081"
"","6.0850","1.2710","6847.3423"
"","6.1850","1.2920","6889.0894"
"","6.2850","1.3141","6922.6475"
"","6.3850","1.3340","6954.7251"
"","6.4850","1.3560","6986.1768"
"","6.5850","1.3762","7013.2295"
"","6.6850","1.3984","7043.0845"
"","6.7850","1.4194","7063.8633"
"","6.8850","1.4403","7091.5781"
"","6.9850","1.4615","7110.3169"
"","7.0850","1.4825","7133.8394"
"","7.1850","1.5047","7152.6343"
"","7.2850","1.5247","7169.9023"
"","7.3850","1.5465","7188.2583"
"","7.4850","1.5670","7202.2310"
"","7.5850","1.5888","7221.5923"
"","7.6850","1.6101","7231.1641"
"","7.7850","1.6307","7250.0557"
"","7.8850","1.6523","7260.2241"
"","7.9850","1.6728","7275.1919"
"","8.0850","1.6949","7287.0078"
"","8.1850","1.7153","7295.8501"
"","8.2850","1.7369","7309.9219"
"","8.3850","1.7575","7316.5625"
"","8.4850","1.7789","7330.1943"
"","8.5850","1.8006","7337.1211"
"","8.6850","1.8211","7349.5791"
"","8.7850","1.8430","7355.9487"
"","8.8850","1.8633","7366.0298"
"","8.9850","1.8855","7375.4253"
"","9.0850","1.9059","7379.0894"
"","9.1850","1.9273","7391.6675"
"","9.2850","1.9484","7395.6528"
"","9.3850","1.9693","7406.5142"
"","9.4850","1.9913","7410.0620"
"","9.5850","2.0115","7417.6392"
"","9.6850","2.0333","7424.4380"
"","9.7850","2.0538","7430.1592"
"","9.8850","2.0757","7438.9429"
"","9.9850","2.0968","7439.6284"
"","10.0850","2.1177","7452.8506"
"","10.1850","2.1390","7452.6401"
"","10.2850","2.1597","7461.5576"
"","10.3850","2.1819","7465.5107"
"","10.4850","2.2020","7469.0947"
"","10.5850","2.2238","7476.5889"
"","10.6850","2.2444","7479.6299"
"","10.7850","2.2659","7487.9536"
"","10.8850","2.2875","7488.0503"
"","10.9850","2.3080","7498.0752"
"","11.0850","2.3295","7498.5532"
"","11.1850","2.3499","7505.2744"
"","11.2850","2.3724","7509.8882"
"","11.3850","2.3928","7510.4634"
"","11.4850","2.4142","7519.3809"
"","11.5850","2.4349","7519.3779"
"","11.6850","2.4564","7528.5430"
"","11.7850","2.4782","7527.1689"
"","11.8850","2.4984","7535.4331"
"","11.9850","2.5201","7536.3687"
"","12.0850","2.5405","7541.3926"
"","12.1850","2.5627","7546.2871"
"","12.2850","2.5832","7544.8623"
"","12.3850","2.6048","7554.7783"
"","12.4850","2.6255","7552.7930"
"","12.5850","2.6468","7561.6357"
"","12.6850","2.6688","7561.2129"
"","12.7850","2.6889","7565.8130"
"","12.8850","2.7107","7569.4414"
"","12.9850","2.7312","7572.1094"
"","13.0850","2.7530","7577.3516"
"","13.1850","2.7741","7574.9917"
"","13.2850","2.7950","7584.1060"
"","13.3850","2.8162","7582.9937"
"","13.4850","2.8370","7589.8833"
"","13.5850","2.8592","7591.3911"
"","13.6850","2.8793","7592.5781"
"","13.7850","2.9011","7597.6826"
"","13.8850","2.9216","7598.5996"
"","13.9850","2.9433","7604.3999"
"","14.0850","2.9649","7602.5210"
"","14.1850","2.9852","7610.0200"
"","14.2850","3.0070","7609.3213"
"","14.3850","3.0275","7614.5513"
"","14.4850","3.0498","7617.1333"
"","14.5850","3.0699","7616.4067"
"","14.6850","3.0917","7622.8613"
"","14.7850","3.1123","7622.0869"
"","14.8850","3.1337","7629.1270"
"","14.9850","3.1552","7626.4561"
"","15.0850","3.1756","7633.6304"
"","15.1850","3.1976","7633.4678"
"","15.2850","3.2179","7636.6978"
"","15.3850","3.2401","7640.9233"
"","15.4850","3.2609","7638.3540"
"","15.5850","3.2821","7646.1309"
"","15.6850","3.3030","7643.6230"
"","15.7850","3.3240","7649.7393"
"","15.8850","3.3460","7649.3799"
"","15.9850","3.3662","7652.8892"
"","16.0850","3.3879","7654.7578"
"","16.1850","3.4084","7658.1880"
"","16.2850","3.4302","7661.3286"
"","16.3850","3.4515","7659.0806"
"","16.4850","3.4722","7665.7334"
"","16.5850","3.4935","7665.0820"
"","16.6850","3.5143","7669.9995"
"","16.7850","3.5366","7671.6899"
"","16.8850","3.5568","7671.0581"
"","16.9850","3.5784","7675.9038"
"","17.0850","3.5990","7675.2476"
"","17.1850","3.6207","7680.5747"
"","17.2850","3.6422","7677.7026"
"","17.3850","3.6627","7685.2241"
"","17.4850","3.6842","7684.2852"
"","17.5850","3.7047","7688.5415"
"","17.6850","3.7269","7690.9990"
"","17.7850","3.7474","7688.2368"
"","17.8850","3.7688","7694.2168"
"","17.9850","3.7896","7693.5527"
"","18.0850","3.8110","7699.0054"
"","18.1850","3.8329","7696.5220"
"","18.2850","3.8532","7701.6338"
"","18.3850","3.8749","7701.9824"
"","18.4850","3.8953","7704.9702"
"","18.5850","3.9174","7708.2842"
"","18.6850","3.9381","7705.0166"
"","18.7850","3.9591","7712.3896"
"","18.8850","3.9804","7709.4712"
"","18.9850","4.0012","7715.6006"
"","19.0850","4.0234","7714.8589"
"","19.1850","4.0435","7716.8779"
"","19.2850","4.0652","7719.8267"
"","19.3850","4.0857","7720.8301"
"","19.4850","4.1076","7724.4580"
"","19.5850","4.1288","7721.1191"
"","19.6850","4.1496","7727.7007"
"","19.7850","4.1709","7724.7515"
"","19.8850","4.1918","7731.0107"
"","19.9850","4.2139","7731.0869"
"","20.0850","4.2341","7732.2759"
"","20.1850","4.2559","7736.3135"
"","20.2850","4.2762","7735.7695"
"","20.3850","4.2979","7739.8584"
"","20.4850","4.3194","7737.1538"
"","20.5850","4.3402","7742.2930"
"","20.6850","4.3613","7741.1055"
"","20.7850","4.3822","7745.4277"
"","20.8850","4.4044","7746.8394"
"","20.9850","4.4249","7745.5908"
"","21.0850","4.4464","7752.1660"
"","21.1850","4.4671","7749.2334"
"","21.2850","4.4884","7755.3301"
"","21.3850","4.5101","7752.3872"
"","21.4850","4.5302","7756.6675"
"","21.5850","4.5521","7757.3149"
"","21.6850","4.5726","7758.3613"
"","21.7850","4.5946","7762.6797"
"","21.8850","4.6155","7757.9951"
"","21.9850","4.6366","7766.2153"
"","22.0850","4.6576","7763.6787"
"","22.1850","4.6786","7768.8389"
"","22.2850","4.7008","7767.9478"
"","22.3850","4.7208","7768.4307"
"","22.4850","4.7427","7771.8511"
"","22.5850","4.7629","7772.2490"
"","22.6850","4.7850","7778.5625"
"","22.7850","4.8062","7775.4053"
"","22.8850","4.8269","7784.3242"
"","22.9850","4.8481","7782.2051"
"","23.0850","4.8690","7786.3687"
"","23.1850","4.8911","7786.5703"
"","23.2850","4.9114","7785.6382"
"","23.3850","4.9331","7789.6133"
"","23.4850","4.9537","7787.6245"
"","23.5850","4.9753","7791.6304"
"","23.6850","4.9971","7786.8765"
"","23.7850","5.0174","7792.2456"
"","23.8850","5.0389","7789.6064"
"","23.9850","5.0596","7790.2710"
"","24.0850","5.0816","7790.4976"
"","24.1850","5.1022","7788.0601"
"","24.2850","5.1235","7793.9106"
"","24.3850","5.1443","7794.3140"
"","24.4850","5.1656","7804.4155"
"","24.5850","5.1875","7805.6807"
"","24.6850","5.2076","7811.2700"
"","24.7850","5.2295","7812.6094"
"","24.8850","5.2499","7814.7583"
"","24.9850","5.2720","7818.2056"
"","25.0850","5.2929","7813.9976"
"","25.1850","5.3139","7821.2612"
"","25.2850","5.3352","7818.5952"
"","25.3850","5.3559","7822.8755"
"","25.4850","5.3780","7822.2773"
"","25.5850","5.3981","7824.7056"
"","25.6850","5.4199","7826.7559"
"","25.7850","5.4403","7828.3066"
"","25.8850","5.4622","7830.8218"
"","25.9850","5.4834","7827.1411"
"","26.0850","5.5043","7834.8369"
"","26.1850","5.5256","7834.1050"
"","26.2850","5.5463","7842.4028"
"","26.3850","5.5686","7843.7979"
"","26.4850","5.5889","7844.9048"
"","26.5850","5.6104","7849.2632"
"","26.6850","5.6312","7849.1660"
"","26.7850","5.6527","7853.6587"
"","26.8850","5.6741","7851.2490"
"","26.9850","5.6947","7856.4443"
"","27.0850","5.7162","7853.5283"
"","27.1850","5.7368","7856.9224"
"","27.2850","5.7590","7859.3247"
"","27.3850","5.7795","7860.6865"
"","27.4850","5.8008","7867.4873"
"","27.5850","5.8217","7867.1240"
"","27.6850","5.8429","7871.7930"
"","27.7850","5.8649","7869.8135"
"","27.8850","5.8849","7872.6709"
"","27.9850","5.9067","7873.2466"
"","28.0850","5.9274","7875.1768"
"","28.1850","5.9493","7877.1646"
"","28.2850","5.9702","7875.0400"
"","28.3850","5.9912","7878.4331"
"","28.4850","6.0121","7874.9478"
"","28.5850","6.0332","7876.7412"
"","28.6850","6.0554","7880.3340"
"","28.7850","6.0756","7886.0605"
"","28.8850","6.0974","7890.6113"
"","28.9850","6.1179","7894.8325"
"","29.0850","6.1396","7901.8423"
"","29.1850","6.1609","7900.6328"
"","29.2850","6.1816","7902.0024"
"","29.3850","6.2029","7886.2080"
"","29.4850","6.2237","7891.3301"
"","29.5850","6.2460","7899.3174"
"","29.6850","6.2661","7901.0864"
"","29.7850","6.2878","7903.4819"
"","29.8850","6.3084","7901.7534"
"","29.9850","6.3299","7901.1909"
"","30.0850","6.3515","7894.1611"
"","30.1850","6.3718","7900.4385"
"","30.2850","6.3936","7901.0425"
"","30.3850","6.4141","7902.5684"
"","30.4850","6.4363","7901.8032"
"","30.5850","6.4569","7901.4937"
"","30.6850","6.4783","7906.0957"
"","30.7850","6.4990","7905.9214"
"","30.8850","6.5201","7910.4385"
"","30.9850","6.5420","7907.5747"
"","31.0850","6.5623","7910.2354"
"","31.1850","6.5842","7911.4170"
"","31.2850","6.6047","7918.9082"
"","31.3850","6.6266","7926.7383"
"","31.4850","6.6476","7929.9727"
"","31.5850","6.6686","7938.8999"
"","31.6850","6.6894","7941.1948"
"","31.7850","6.7105","7946.5264"
"","31.8850","6.7327","7948.0464"
"","31.9850","6.7530","7949.1035"
"","32.0850","6.7748","7951.6055"
"","32.1850","6.7952","7952.7817"
"","32.2850","6.8170","7957.2505"
"","32.3850","6.8383","7957.1328"
"","32.4850","6.8589","7970.3643"
"","32.5850","6.8802","7984.0547"
"","32.6850","6.9008","7999.1577"
"","32.7850","6.9232","7950.4966"
"","32.8850","6.9435","7943.5332"
"","32.9850","6.9651","7955.8516"
"","33.0850","6.9857","7958.1885"
"","33.1850","7.0074","7931.8120"
"","33.2850","7.0290","7920.9419"
"","33.3850","7.0493","7919.1968"
"","33.4850","7.0709","7925.5132"
"","33.5850","7.0912","7932.6860"
"","33.6850","7.1137","7933.6206"
"","33.7850","7.1342","7931.7471"
"","33.8850","7.1555","7933.7739"
"","33.9850","7.1764","7932.1182"
"","34.0850","7.1977","7932.7480"
"","34.1850","7.2194","7929.5293"
"","34.2850","7.2397","7930.1826"
"","34.3850","7.2612","7927.9243"
"","34.4850","7.2819","7928.5635"
"","34.5850","7.3040","7931.2480"
"","34.6850","7.3249","7930.1709"
"","34.7850","7.3461","7936.4238"
"","34.8850","7.3672","7937.1670"
"","34.9850","7.3880","7944.2314"
"","35.0850","7.4101","7947.5137"
"","35.1850","7.4303","7951.6016"
"","35.2850","7.4520","7955.4009"
"","35.3850","7.4726","7958.1226"
"","35.4850","7.4941","7962.1836"
"","35.5850","7.5156","7960.9282"
"","35.6850","7.5361","7966.8887"
"","35.7850","7.5577","7966.2456"
"","35.8850","7.5781","7971.5088"
"","35.9850","7.6006","7973.2246"
"","36.0850","7.6209","7974.0996"
"","36.1850","7.6426","7976.4956"
"","36.2850","7.6630","7975.5088"
"","36.3850","7.6846","7978.4893"
"","36.4850","7.7062","7975.5972"
"","36.5850","7.7266","7979.5352"
"","36.6850","7.7482","7977.5234"
"","36.7850","7.7687","7979.4287"
"","36.8850","7.7910","7980.0405"
"","36.9850","7.8113","7978.7476"
"","37.0850","7.8330","7981.5767"
"","37.1850","7.8536","7980.6396"
"","37.2850","7.8748","7984.2979"
"","37.3850","7.8969","7983.3784"
"","37.4850","7.9172","7987.4023"
"","37.5850","7.9389","7987.2578"
"","37.6850","7.9592","7990.9580"
"","37.7850","7.9813","7993.6416"
"","37.8850","8.0022","7994.1211"
"","37.9850","8.0233","8000.2866"
"","38.0850","8.0443","7998.7690"
"","38.1850","8.0652","8002.8618"
"","38.2850","8.0874","8000.3052"
"","38.3850","8.1075","7999.8716"
"","38.4850","8.1294","7997.8125"
"","38.5850","8.1499","7997.1729"
"","38.6850","8.1715","7999.6416"
"","38.7850","8.1930","7998.3511"
"","38.8850","8.2136","8003.9932"
"","38.9850","8.2349","8002.3975"
"","39.0850","8.2556","8004.6997"
"","39.1850","8.2778","8004.3086"
"","39.2850","8.2983","8001.5288"
"","39.3850","8.3197","8002.1567"
"","39.4850","8.3402","8000.8477"
"","39.5850","8.3617","8004.2944"
"","39.6850","8.3836","8002.1880"
"","39.7850","8.4038","8005.2520"
"","39.8850","8.4255","8004.1865"
"","39.9850","8.4461","8004.4580"
"","40.0850","8.4682","8005.5796"
"","40.1850","8.4890","8003.7632"
"","40.2850","8.5102","8007.3701"
"","40.3850","8.5311","8006.9331"
"","40.4850","8.5523","8011.6733"
"","40.5850","8.5743","8009.8184"
"","40.6850","8.5944","8013.0659"
"","40.7850","8.6159","8012.3760"
"","40.8850","8.6365","8016.1465"
"","40.9850","8.6586","8020.0376"
"","41.0850","8.6796","8020.1030"
"","41.1850","8.7005","8027.6987"
"","41.2850","8.7218","8027.2295"
"","41.3850","8.7425","8032.2690"
"","41.4850","8.7648","8034.4932"
"","41.5850","8.7849","8036.9702"
"","41.6850","8.8068","8039.7280"
"","41.7850","8.8272","8042.5249"
"","41.8850","8.8490","8046.5088"
"","41.9850","8.8702","8046.3564"
"","42.0850","8.8908","8051.0430"
"","42.1850","8.9123","8049.5195"
"","42.2850","8.9327","8051.7056"
"","42.3850","8.9549","8054.7241"
"","42.4850","8.9755","8056.4380"
"","42.5850","8.9972","8062.9409"
"","42.6850","9.0179","8067.1572"
"","42.7850","9.0392","8073.1606"
"","42.8850","9.0611","8072.6152"
"","42.9850","9.0812","8076.1147"
"","43.0850","9.1030","8075.1313"
"","43.1850","9.1233","8082.9263"
"","43.2850","9.1456","8099.3823"
"","43.3850","9.1663","8112.7954"
"","43.4850","9.1875","8127.7915"
"","43.5850","9.2085","8129.0552"
"","43.6850","9.2295","8135.0488"
"","43.7850","9.2516","8129.5923"
"","43.8850","9.2717","8068.5952"
"","43.9850","9.2936","8068.6279"
"","44.0850","9.3139","8065.4761"
"","44.1850","9.3359","8064.4966"
"","44.2850","9.3570","8057.7031"
"","44.3850","9.3780","8055.4487"
"","44.4850","9.3991","8044.8066"
"","44.5850","9.4198","8041.6040"
"","44.6850","9.4423","8033.7070"
"","44.7850","9.4621","8034.2954"
"","44.8850","9.4838","8035.5972"
"","44.9850","9.5044","8036.4795"
"","45.0850","9.5261","8037.6694"
"","45.1850","9.5476","8034.5972"
"","45.2850","9.5683","8036.9204"
"","45.3850","9.5897","8032.7852"
"","45.4850","9.6104","8033.7480"
"","45.5850","9.6324","8032.1118"
"","45.6850","9.6529","8030.2173"
"","45.7850","9.6744","8029.9927"
"","45.8850","9.6952","8029.1631"
"","45.9850","9.7165","8032.6206"
"","46.0850","9.7384","8030.7881"
"","46.1850","9.7586","8035.8071"
"","46.2850","9.7803","8035.7896"
"","46.3850","9.8009","8038.8501"
"","46.4850","9.8228","8042.2207"
"","46.5850","9.8436","8041.7646"
"","46.6850","9.8649","8047.6104"
"","46.7850","9.8858","8047.3418"
"","46.8850","9.9068","8052.7993"
"","46.9850","9.9291","8052.1299"
"","47.0850","9.9491","8056.3320"
"","47.1850","9.9710","8056.9380"
"","47.2850","9.9911","8059.6699"
"","47.3850","10.0131","8062.2515"
"","47.4850","10.0342","8060.7905"
"","47.5850","10.0551","8066.1162"
"","47.6850","10.0764","8064.3027"
"","47.7850","10.0972","8067.7847"
"","47.8850","10.1193","8068.1465"
"","47.9850","10.1396","8069.2085"
"","48.0850","10.1613","8070.1978"
"","48.1850","10.1818","8070.7432"
"","48.2850","10.2034","8072.5068"
"","48.3850","10.2249","8069.2759"
"","48.4850","10.2455","8073.0708"
"","48.5850","10.2671","8070.1030"
"","48.6850","10.2877","8072.6035"
"","48.7850","10.3096","8073.3867"
"","48.8850","10.3303","8071.1909"
"","48.9850","10.3518","8074.0869"
"","49.0850","10.3724","8073.3643"
"","49.1850","10.3937","8076.3535"
"","49.2850","10.4157","8073.8975"
"","49.3850","10.4359","8078.2510"
"","49.4850","10.4577","8076.6382"
"","49.5850","10.4780","8078.7949"
"","49.6850","10.5002","8080.5273"
"","49.7850","10.5211","8079.8491"
"","49.8850","10.5422","8084.4946"
"","49.9850","10.5631","8084.0791"
"","50.0850","10.5842","8088.4263"
"","50.1850","10.6062","8086.8804"
"","50.2850","10.6264","8089.7437"
"","50.3850","10.6481","8089.4844"
"","50.4850","10.6685","8091.5459"
"","50.5850","10.6905","8092.1138"
"","50.6850","10.7116","8089.3779"
"","50.7850","10.7324","8093.2222"
"","50.8850","10.7537","8089.7485"
"","50.9850","10.7746","8092.0176"
"","51.0850","10.7967","8091.8193"
"","51.1850","10.8169","8090.7397"
"","51.2850","10.8386","8091.9995"
"","51.3850","10.8593","8091.6406"
"","51.4850","10.8809","8094.6997"
"","51.5850","10.9022","8092.4487"
"","51.6850","10.9228","8096.2168"
"","51.7850","10.9443","8093.5195"
"","51.8850","10.9650","8094.7407"
"","51.9850","10.9871","8094.1401"
"","52.0850","11.0074","8093.0010"
"","52.1850","11.0292","8094.2622"
"","52.2850","11.0499","8092.9248"
"","52.3850","11.0712","8095.0977"
"","52.4850","11.0930","8093.0508"
"","52.5850","11.1133","8096.4951"
"","52.6850","11.1350","8094.0137"
"","52.7850","11.1555","8096.5132"
"","52.8850","11.1776","8096.3232"
"","52.9850","11.1982","8095.5645"
"","53.0850","11.2196","8097.8779"
"","53.1850","11.2405","8096.1099"
"","53.2850","11.2613","8099.8721"
"","53.3850","11.2835","8099.1841"
"","53.4850","11.3037","8102.0171"
"","53.5850","11.3255","8101.9512"
"","53.6850","11.3459","8102.7344"
"","53.7850","11.3676","8106.5908"
"","53.8850","11.3890","8104.8721"
"","53.9850","11.4099","8111.0410"
"","54.0850","11.4312","8109.4058"
"","54.1850","11.4518","8114.7866"
"","54.2850","11.4741","8115.1240"
"","54.3850","11.4942","8116.9961"
"","54.4850","11.5162","8118.7002"
"","54.5850","11.5363","8119.8657"
"","54.6850","11.5581","8122.8682"
"","54.7850","11.5797","8119.6250"
"","54.8850","11.6000","8126.9556"
"","54.9850","11.6217","8123.5586"
"","55.0850","11.6423","8128.2305"
"","55.1850","11.6646","8128.4277"
"","55.2850","11.6849","8130.7021"
"","55.3850","11.7065","8132.6777"
"","55.4850","11.7272","8133.9717"
"","55.5850","11.7486","8139.0435"
"","55.6850","11.7704","8139.0059"
"","55.7850","11.7906","8146.5269"
"","55.8850","11.8121","8150.6343"
"","55.9850","11.8327","8160.0532"
"","56.0850","11.8547","8167.5820"
"","56.1850","11.8756","8172.7246"
"","56.2850","11.8967","8181.4297"
"","56.3850","11.9177","8184.9849"
"","56.4850","11.9388","8191.7358"
"","56.5850","11.9610","8192.9951"
"","56.6850","11.9812","8195.1006"
"","56.7850","12.0028","8191.8203"
"","56.8850","12.0234","8188.1089"
"","56.9850","12.0451","8186.4082"
"","57.0850","12.0662","8181.1460"
"","57.1850","12.0870","8184.9053"
"","57.2850","12.1085","8179.7979"
"","57.3850","12.1293","8181.9082"
"","57.4850","12.1512","8179.8037"
"","57.5850","12.1718","8178.4531"
"","57.6850","12.1933","8177.2031"
"","57.7850","12.2139","8175.9795"
"","57.8850","12.2355","8175.8062"
"","57.9850","12.2570","8170.8335"
"","58.0850","12.2775","8173.7720"
"","58.1850","12.2991","8168.8774"
"","58.2850","12.3197","8169.9810"
"","58.3850","12.3419","8168.0820"
"","58.4850","12.3623","8165.8491"
"","58.5850","12.3837","8166.7134"
"","58.6850","12.4044","8163.6318"
"","58.7850","12.4256","8164.0176"
"","58.8850","12.4474","8160.0303"
"","58.9850","12.4679","8161.5342"
"","59.0850","12.4897","8159.4556"
"","59.1850","12.5101","8160.6978"
"","59.2850","12.5322","8160.9888"
"","59.3850","12.5530","8159.0801"
"","59.4850","12.5742","8161.6709"
"","59.5850","12.5951","8158.4780"
"","59.6850","12.6160","8160.4966"
"","59.7850","12.6382","8157.8687"
"","59.8850","12.6584","8157.9546"
"","59.9850","12.6802","8157.9111"
"","60.0850","12.7006","8159.6201"
"","60.1850","12.7222","8160.4277"
"","60.2850","12.7436","8157.7271"
"","60.3850","12.7645","8162.1533"
"","60.4850","12.7857","8159.1943"
"","60.5850","12.8065","8162.3228"
"","60.6850","12.8289","8161.1226"
"","60.7850","12.8490","8160.1792"
"","60.8850","12.8707","8159.6357"
"","60.9850","12.8913","8159.0020"
"","61.0850","12.9129","8161.3101"
"","61.1850","12.9345","8158.8047"
"","61.2850","12.9548","8161.7378"
"","61.3850","12.9762","8159.5264"
"","61.4850","12.9969","8160.8994"
"","61.5850","13.0192","8160.4341"
"","61.6850","13.0394","8158.6177"
"","61.7850","13.0610","8160.2148"
"","61.8850","13.0818","8159.1719"
"","61.9850","13.1031","8161.3989"
"","62.0850","13.1251","8158.2500"
"","62.1850","13.1452","8161.4629"
"","62.2850","13.1670","8158.8193"
"","62.3850","13.1874","8159.7192"
"","62.4850","13.2095","8159.7021"
"","62.5850","13.2302","8156.5796"
"","62.6850","13.2515","8159.3706"
"","62.7850","13.2724","8155.2446"
"","62.8850","13.2935","8157.3652"
"","62.9850","13.3155","8153.9287"
"","63.0850","13.3356","8153.8447"
"","63.1850","13.3576","8152.3618"
"","63.2850","13.3781","8152.5557"
"","63.3850","13.3998","8151.7505"
"","63.4850","13.4211","8148.0303"
"","63.5850","13.4419","8151.2690"
"","63.6850","13.4632","8147.5288"
"","63.7850","13.4839","8149.3477"
"","63.8850","13.5060","8147.9663"
"","63.9850","13.5263","8147.3237"
"","64.0850","13.5480","8147.1289"
"","64.1850","13.5685","8147.3008"
"","64.2850","13.5900","8148.6650"
"","64.3850","13.6117","8145.5059"
"","64.4850","13.6320","8149.0361"
"","64.5850","13.6537","8145.6699"
"","64.6850","13.6742","8147.5132"
"","64.7850","13.6963","8147.9707"
"","64.8850","13.7170","8145.5469"
"","64.9850","13.7383","8147.2383"
"","65.0850","13.7593","8144.2656"
"","65.1850","13.7804","8147.0557"
"","65.2850","13.8023","8143.0801"
"","65.3850","13.8225","8146.0049"
"","65.4850","13.8444","8142.7939"
"","65.5850","13.8646","8143.2939"
"","65.6850","13.8866","8143.4995"
"","65.7850","13.9077","8139.1978"
"","65.8850","13.9287","8141.9595"
"","65.9850","13.9498","8137.1284"
"","66.0850","13.9708","8138.2417"
"","66.1850","13.9930","8134.9546"
"","66.2850","14.0132","8134.8232"
"","66.3850","14.0350","8132.7266"
"","66.4850","14.0553","8131.5166"
"","66.5850","14.0772","8130.7480"
"","66.6850","14.0982","8126.5381"
"","66.7850","14.1191","8127.8296"
"","66.8850","14.1404","8121.9590"
"","66.9850","14.1611","8122.9658"
"","67.0850","14.1835","8120.4580"
"","67.1850","14.2037","8118.1543"
"","67.2850","14.2253","8118.1021"
"","67.3850","14.2459","8117.1172"
"","67.4850","14.2673","8118.3745"
"","67.5850","14.2891","8113.2441"
"","67.6850","14.3094","8116.2446"
"","67.7850","14.3311","8114.0532"
"","67.8850","14.3517","8116.4785"
"","67.9850","14.3738","8117.8008"
"","68.0850","14.3943","8116.9902"
"","68.1850","14.4155","8121.0718"
"","68.2850","14.4364","8118.5410"
"","68.3850","14.4576","8121.3906"
"","68.4850","14.4796","8119.0830"
"","68.5850","14.4998","8121.8892"
"","68.6850","14.5217","8120.0049"
"","68.7850","14.5423","8122.6587"
"","68.8850","14.5642","8124.2681"
"","68.9850","14.5850","8123.3794"
"","69.0850","14.6062","8128.4834"
"","69.1850","14.6273","8125.9370"
"","69.2850","14.6480","8130.3179"
"","69.3850","14.6703","8129.0225"
"","69.4850","14.6904","8131.1548"
"","69.5850","14.7121","8132.4951"
"","69.6850","14.7327","8135.1104"
"","69.7850","14.7543","8141.0439"
"","69.8850","14.7757","8145.4634"
"","69.9850","14.7964","8158.5234"
"","70.0850","14.8177","8165.9863"
"","70.1850","14.8384","8180.9448"
"","70.2850","14.8607","8189.8125"
"","70.3850","14.8810","8187.9863"
"","70.4850","14.9028","8190.5259"
"","70.5850","14.9234","8190.3970"
"","70.6850","14.9448","8192.4121"
"","70.7850","14.9664","8186.3521"
"","70.8850","14.9865","8188.2432"
"","70.9850","15.0084","8181.6436"
"","71.0850","15.0287","8180.6040"
"","71.1850","15.0511","8178.2705"
"","71.2850","15.0717","8175.9600"
"","71.3850","15.0931","8178.7163"
"","71.4850","15.1138","8174.7158"
"","71.5850","15.1350","8176.8179"
"","71.6850","15.1572","8171.0825"
"","71.7850","15.1770","8172.8340"
"","71.8850","15.1991","8168.3921"
"","71.9850","15.2194","8169.9214"
"","72.0850","15.2415","8169.3335"
"","72.1850","15.2626","8166.3462"
"","72.2850","15.2834","8171.0337"
"","72.3850","15.3045","8167.6064"
"","72.4850","15.3255","8169.9463"
"","72.5850","15.3476","8169.2300"
"","72.6850","15.3677","8171.5718"
"","72.7850","15.3894","8171.2686"
"","72.8850","15.4100","8173.1631"
"","72.9850","15.4317","8175.1318"
"","73.0850","15.4529","8172.5312"
"","73.1850","15.4737","8178.2573"
"","73.2850","15.4953","8176.2871"
"","73.3850","15.5158","8180.2227"
"","73.4850","15.5380","8180.4424"
"","73.5850","15.5584","8179.7568"
"","73.6850","15.5799","8180.8901"
"","73.7850","15.6006","8181.2593"
"","73.8850","15.6221","8183.9487"
"","73.9850","15.6436","8181.6025"
"","74.0850","15.6641","8187.2700"
"","74.1850","15.6857","8183.6396"
"","74.2850","15.7063","8187.1987"
"","74.3850","15.7283","8187.1636"
"","74.4850","15.7491","8186.5249"
"","74.5850","15.7704","8188.2627"
"","74.6850","15.7913","8186.7681"
"","74.7850","15.8125","8189.8062"
"","74.8850","15.8344","8186.7373"
"","74.9850","15.8546","8189.5801"
"","75.0850","15.8762","8188.0576"
"","75.1850","15.8968","8190.0967"
"","75.2850","15.9187","8190.4380"
"","75.3850","15.9397","8187.8638"
"","75.4850","15.9607","8192.1104"
"","75.5850","15.9819","8188.9653"
"","75.6850","16.0027","8191.2520"
"","75.7850","16.0249","8189.6206"
"","75.8850","16.0452","8189.8101"
"","75.9850","16.0668","8189.3169"
"","76.0850","16.0874","8190.4829"
"","76.1850","16.1090","8191.8999"
"","76.2850","16.1304","8188.2529"
"","76.3850","16.1511","8193.1230"
"","76.4850","16.1724","8189.0674"
"","76.5850","16.1929","8191.9541"
"","76.6850","16.2153","8190.6831"
"","76.7850","16.2358","8190.3594"
"","76.8850","16.2571","8192.6514"
"","76.9850","16.2780","8191.5542"
"","77.0850","16.2994","8195.0420"
"","77.1850","16.3212","8191.4565"
"","77.2850","16.3415","8196.5186"
"","77.3850","16.3630","8191.9844"
"","77.4850","16.3836","8195.3838"
"","77.5850","16.4058","8195.9082"
"","77.6850","16.4264","8195.1738"
"","77.7850","16.4477","8198.0898"
"","77.8850","16.4685","8197.0908"
"","77.9850","16.4897","8200.2109"
"","78.0850","16.5116","8197.9707"
"","78.1850","16.5319","8200.1846"
"","78.2850","16.5534","8198.6924"
"","78.3850","16.5742","8199.6191"
"","78.4850","16.5961","8200.0654"
"","78.5850","16.6171","8198.4482"
"","78.6850","16.6381","8202.3662"
"","78.7850","16.6591","8198.9502"
"","78.8850","16.6801","8201.9453"
"","78.9850","16.7023","8199.7891"
"","79.0850","16.7224","8199.8604"
"","79.1850","16.7442","8200.6660"
"","79.2850","16.7647","8201.6279"
"","79.3850","16.7863","8203.6982"
"","79.4850","16.8078","8199.6855"
"","79.5850","16.8281","8205.4258"
"","79.6850","16.8497","8199.9785"
"","79.7850","16.8705","8201.7881"
"","79.8850","16.8927","8201.1885"
"","79.9850","16.9132","8200.4961"
"","80.0850","16.9348","8201.6641"
"","80.1850","16.9554","8201.2754"
"","80.2850","16.9768","8204.1387"
"","80.3850","16.9984","8200.5098"
"","80.4850","17.0187","8204.1494"
"","80.5850","17.0405","8200.7695"
"","80.6850","17.0608","8202.4883"
"","80.7850","17.0830","8202.2109"
"","80.8850","17.1037","8200.3887"
"","80.9850","17.1251","8202.8701"
"","81.0850","17.1458","8202.2227"
"","81.1850","17.1669","8203.3604"
"","81.2850","17.1891","8200.1846"
"","81.3850","17.2092","8202.6768"
"","81.4850","17.2310","8199.1494"
"","81.5850","17.2514","8200.1963"
"","81.6850","17.2734","8201.2754"
"","81.7850","17.2946","8199.0879"
"","81.8850","17.3154","8205.0947"
"","81.9850","17.3365","8201.2061"
"","82.0850","17.3573","8204.2295"
"","82.1850","17.3794","8201.2109"
"","82.2850","17.3996","8200.7070"
"","82.3850","17.4214","8199.6895"
"","82.4850","17.4419","8200.6523"
"","82.5850","17.4638","8202.4375"
"","82.6850","17.4853","8199.9873"
"","82.7850","17.5059","8205.6348"
"","82.8850","17.5272","8201.9795"
"","82.9850","17.5478","8204.4141"
"","83.0850","17.5700","8203.8447"
"","83.1850","17.5904","8202.1943"
"","83.2850","17.6118","8203.2188"
"","83.3850","17.6326","8203.1455"
"","83.4850","17.6541","8206.3301"
"","83.5850","17.6759","8204.4512"
"","83.6850","17.6961","8208.7852"
"","83.7850","17.7178","8206.2900"
"","83.8850","17.7381","8208.7842"
"","83.9850","17.7603","8208.3779"
"","84.0850","17.7811","8205.9014"
"","84.1850","17.8024","8210.1162"
"","84.2850","17.8234","8207.4629"
"","84.3850","17.8443","8212.7314"
"","84.4850","17.8665","8209.3984"
"","84.5850","17.8865","8212.9355"
"","84.6850","17.9082","8211.2627"
"","84.7850","17.9287","8212.3926"
"","84.8850","17.9506","8212.6895"
"","84.9850","17.9715","8209.4932"
"","85.0850","17.9927","8215.1377"
"","85.1850","18.0138","8211.8477"
"","85.2850","18.0348","8216.5967"
"","85.3850","18.0570","8215.2959"
"","85.4850","18.0773","8216.6729"
"","85.5850","18.0988","8216.3867"
"","85.6850","18.1194","8216.0479"
"","85.7850","18.1411","8216.4512"
"","85.8850","18.1625","8211.6016"
"","85.9850","18.1829","8213.8066"
"","86.0850","18.2044","8209.9951"
"","86.1850","18.2251","8212.9707"
"","86.2850","18.2473","8214.3877"
"","86.3850","18.2678","8215.8721"
"","86.4850","18.2893","8221.7861"
"","86.5850","18.3100","8223.4053"
"","86.6850","18.3313","8229.7158"
"","86.7850","18.3533","8228.3594"
"","86.8850","18.3735","8234.4082"
"","86.9850","18.3952","8231.9111"
"","87.0850","18.4156","8232.9121"
"","87.1850","18.4375","8232.8623"
"","87.2850","18.4584","8227.3066"
"","87.3850","18.4796","8229.4424"
"","87.4850","18.5004","8219.9590"
"","87.5850","18.5215","8213.2383"
"","87.6850","18.5438","8206.8574"
"","87.7850","18.5637","8222.6348"
"","87.8850","18.5857","8241.2285"
"","87.9850","18.6061","8255.6787"
"","88.0850","18.6280","8265.8018"
"","88.1850","18.6492","8267.3545"
"","88.2850","18.6701","8276.5293"
"","88.3850","18.6914","8274.3008"
"","88.4850","18.7119","8278.9316"
"","88.5850","18.7343","8274.5801"
"","88.6850","18.7544","8273.3896"
"","88.7850","18.7761","8268.8369"
"","88.8850","18.7967","8263.6641"
"","88.9850","18.8183","8260.4414"
"","89.0850","18.8400","8247.9844"
"","89.1850","18.8603","8246.0156"
"","89.2850","18.8819","8233.8516"
"","89.3850","18.9025","8231.6260"
"","89.4850","18.9247","8226.5645"
"","89.5850","18.9451","8222.9736"
"","89.6850","18.9666","8223.4092"
"","89.7850","18.9872","8220.2773"
"","89.8850","19.0087","8221.2812"
"","89.9850","19.0304","8214.6719"
"","90.0850","19.0508","8217.1172"
"","90.1850","19.0724","8211.3350"
"","90.2850","19.0928","8211.5410"
"","90.3850","19.1148","8209.3613"
"","90.4850","19.1357","8205.2676"
"","90.5850","19.1570","8207.2207"
"","90.6850","19.1779","8203.2354"
"","90.7850","19.1990","8205.2305"
"","90.8850","19.2211","8201.1367"
"","90.9850","19.2411","8202.4316"
"","91.0850","19.2630","8198.7178"
"","91.1850","19.2834","8199.9590"
"","91.2850","19.3054","8198.5127"
"","91.3850","19.3265","8194.5439"
"","91.4850","19.3473","8199.9990"
"","91.5850","19.3688","8193.4756"
"","91.6850","19.3893","8198.0566"
"","91.7850","19.4116","8194.6924"
"","91.8850","19.4318","8194.8086"
"","91.9850","19.4535","8193.2021"
"","92.0850","19.4740","8194.2100"
"","92.1850","19.4957","8194.1279"
"","92.2850","19.5173","8190.1162"
"","92.3850","19.5378","8195.4648"
"","92.4850","19.5591","8191.2554"
"","92.5850","19.5796","8194.1328"
"","92.6850","19.6021","8191.8223"
"","92.7850","19.6224","8190.5752"
"","92.8850","19.6439","8191.8022"
"","92.9850","19.6646","8190.6626"
"","93.0850","19.6860","8194.2197"
"","93.1850","19.7079","8191.2046"
"","93.2850","19.7280","8195.9512"
"","93.3850","19.7498","8191.5630"
"","93.4850","19.7702","8194.0322"
"","93.5850","19.7921","8192.0293"
"","93.6850","19.8132","8189.5352"
"","93.7850","19.8343","8193.1191"
"","93.8850","19.8554","8190.9126"
"","93.9850","19.8762","8195.8096"
"","94.0850","19.8985","8191.9492"
"","94.1850","19.9186","8194.5654"
"","94.2850","19.9402","8193.0811"
"","94.3850","19.9608","8194.1973"
"","94.4850","19.9825","8194.3242"
"","94.5850","20.0039","8191.2368"
"","94.6850","20.0246","8196.9287"
"","94.7850","20.0460","8193.1299"
"","94.8850","20.0667","8196.4150"
"","94.9850","20.0891","8195.5459"
"","95.0850","20.1091","8196.4912"
"","95.1850","20.1309","8196.5176"
"","95.2850","20.1514","8196.2627"
"","95.3850","20.1729","8196.9160"
"","95.4850","20.1945","8192.9951"
"","95.5850","20.2149","8197.9160"
"","95.6850","20.2366","8194.0068"
"","95.7850","20.2571","8197.7168"
"","95.8850","20.2793","8196.6279"
"","95.9850","20.2998","8196.2471"
"","96.0850","20.3212","8197.9336"
"","96.1850","20.3419","8195.4766"
"","96.2850","20.3631","8198.6338"
"","96.3850","20.3851","8193.7139"
"","96.4850","20.4055","8198.6699"
"","96.5850","20.4273","8196.0742"
"","96.6850","20.4477","8199.6533"
"","96.7850","20.4695","8199.2939"
"","96.8850","20.4905","8196.2969"
"","96.9850","20.5116","8200.0254"
"","97.0850","20.5326","8195.9727"
"","97.1850","20.5536","8198.3643"
"","97.2850","20.5757","8196.3721"
"","97.3850","20.5959","8197.4668"
"","97.4850","20.6177","8196.8242"
"","97.5850","20.6381","8197.2490"
"","97.6850","20.6599","8198.7412"
"","97.7850","20.6813","8194.9766"
"","97.8850","20.7019","8200.1240"
"","97.9850","20.7234","8196.0430"
"","98.0850","20.7439","8199.0000"
"","98.1850","20.7662","8197.3818"
"","98.2850","20.7865","8196.3945"
"","98.3850","20.8083","8197.8867"
"","98.4850","20.8286","8196.9248"
"","98.5850","20.8503","8199.3311"
"","98.6850","20.8719","8195.1992"
"","98.7850","20.8922","8200.1504"
"","98.8850","20.9137","8193.9150"
"","98.9850","20.9342","8197.3799"
"","99.0850","20.9567","8196.0459"
"","99.1850","20.9772","8194.6641"
"","99.2850","20.9986","8197.6348"
"","99.3850","21.0195","8195.3359"
"","99.4850","21.0407","8198.2461"
"","99.5850","21.0625","8194.6357"
"","99.6850","21.0828","8198.2666"
"","99.7850","21.1044","8195.2012"
"","99.8850","21.1250","8196.5605"
"","99.9850","21.1469","8196.0840"
"","100.0850","21.1677","8193.8389"
"","100.1850","21.1889","8197.1279"
"","100.2850","21.2100","8195.1855"
"","100.3850","21.2309","8196.8467"
"","100.4850","21.2531","8196.0332"
"","100.5850","21.2733","8196.2275"
"","100.6850","21.2951","8195.3154"
"","100.7850","21.3156","8196.1064"
"","100.8850","21.3373","8197.6826"
"","100.9850","21.3586","8193.8018"
"","101.0850","21.3792","8198.9873"
"","101.1850","21.4007","8194.6221"
"","101.2850","21.4212","8198.4453"
"","101.3850","21.4434","8197.0479"
"","101.4850","21.4638","8196.0117"
"","101.5850","21.4854","8197.6533"
"","101.6850","21.5061","8196.9219"
"","101.7850","21.5276","8198.8115"
"","101.8850","21.5492","8195.0342"
"","101.9850","21.5696","8199.4648"
"","102.0850","21.5913","8195.1377"
"","102.1850","21.6118","8198.1494"
"","102.2850","21.6339","8197.1924"
"","102.3850","21.6545","8195.2148"
"","102.4850","21.6759","8198.1436"
"","102.5850","21.6967","8195.6611"
"","102.6850","21.7177","8198.5283"
"","102.7850","21.7399","8194.9893"
"","102.8850","21.7600","8198.2939"
"","102.9850","21.7819","8195.1943"
"","103.0850","21.8023","8197.5977"
"","103.1850","21.8243","8198.0527"
"","103.2850","21.8453","8195.4551"
"","103.3850","21.8663","8199.4316"
"","103.4850","21.8873","8194.6357"
"","103.5850","21.9082","8198.0283"
"","103.6850","21.9305","8194.3174"
"","103.7850","21.9505","8195.6709"
"","103.8850","21.9723","8194.8516"
"","103.9850","21.9928","8196.0645"
"","104.0850","22.0143","8196.7354"
"","104.1850","22.0359","8192.4512"
"","104.2850","22.0565","8197.5098"
"","104.3850","22.0779","8192.8213"
"","104.4850","22.0988","8195.5205"
"","104.5850","22.1208","8194.1709"
"","104.6850","22.1414","8192.8545"
"","104.7850","22.1627","8194.2246"
"","104.8850","22.1835","8191.5327"
"","104.9850","22.2047","8194.3350"
"","105.0850","22.2267","8189.4189"
"","105.1850","22.2469","8193.7803"
"","105.2850","22.2686","8190.3145"
"","105.3850","22.2889","8191.5698"
"","105.4850","22.3111","8192.7617"
"","105.5850","22.3320","8189.3096"
"","105.6850","22.3530","8193.1797"
"","105.7850","22.3742","8190.7974"
"","105.8850","22.3953","8193.9834"
"","105.9850","22.4174","8190.2114"
"","106.0850","22.4374","8193.3613"
"","106.1850","22.4593","8191.1616"
"","106.2850","22.4797","8194.0674"
"","106.3850","22.5017","8195.0107"
"","106.4850","22.5224","8192.6904"
"","106.5850","22.5436","8198.5283"
"","106.6850","22.5645","8194.6221"
"","106.7850","22.5855","8199.4229"
"","106.8850","22.6074","8197.8818"
"","106.9850","22.6279","8200.7500"
"","107.0850","22.6498","8200.8916"
"","107.1850","22.6702","8203.9941"
"","107.2850","22.6919","8204.8789"
"","107.3850","22.7131","8202.9912"
"","107.4850","22.7340","8207.3740"
"","107.5850","22.7553","8203.2842"
"","107.6850","22.7759","8207.8975"
"","107.7850","22.7982","8207.9805"
"","107.8850","22.8187","8210.1670"
"","107.9850","22.8401","8213.5732"
"","108.0850","22.8608","8214.7646"
"","108.1850","22.8822","8217.8828"
"","108.2850","22.9038","8215.9365"
"","108.3850","22.9242","8220.9736"
"","108.4850","22.9459","8218.8662"
"","108.5850","22.9664","8222.5674"
"","108.6850","22.9887","8224.3242"
"","108.7850","23.0094","8223.8750"
"","108.8850","23.0307","8228.5273"
"","108.9850","23.0514","8227.3301"
"","109.0850","23.0725","8231.5479"
"","109.1850","23.0945","8230.1992"
"","109.2850","23.1147","8233.2607"
"","109.3850","23.1364","8234.4150"
"","109.4850","23.1568","8238.5957"
"","109.5850","23.1789","8243.4033"
"","109.6850","23.1999","8246.3486"
"","109.7850","23.2210","8259.1182"
"","109.8850","23.2419","8266.7012"
"","109.9850","23.2629","8280.2100"
"","110.0850","23.2850","8281.6465"
"","110.1850","23.3051","8276.1484"
"","110.2850","23.3270","8269.3691"
"","110.3850","23.3475","8264.6484"
"","110.4850","23.3692","8259.9453"
"","110.5850","23.3906","8250.3857"
"","110.6850","23.4114","8247.4131"
"","110.7850","23.4325","8236.0000"
"","110.8850","23.4532","8230.7803"
"","110.9850","23.4754","8221.3076"
"","111.0850","23.4958","8214.2275"
"","111.1850","23.5175","8210.2842"
"","111.2850","23.5382","8204.5498"
"","111.3850","23.5595","8202.9385"
"","111.4850","23.5814","8196.2021"
"","111.5850","23.6017","8196.9131"
"","111.6850","23.6234","8189.9204"
"","111.7850","23.6438","8189.6948"
"","111.8850","23.6658","8186.7417"
"","111.9850","23.6866","8181.3833"
"","112.0850","23.7079","8182.2051"
"","112.1850","23.7286","8176.8999"
"","112.2850","23.7499","8178.3345"
"","112.3850","23.7719","8173.1997"
"","112.4850","23.7920","8175.4819"
"","112.5850","23.8139","8171.2617"
"","112.6850","23.8342","8171.6782"
"","112.7850","23.8562","8170.9683"
"","112.8850","23.8773","8166.0991"
"","112.9850","23.8981","8170.5400"
"","113.0850","23.9194","8164.5801"
"","113.1850","23.9402","8168.3286"
"","113.2850","23.9624","8164.3789"
"","113.3850","23.9825","8166.2295"
"","113.4850","24.0043","8164.1167"
"","113.5850","24.0248","8164.1958"
"","113.6850","24.0465","8165.7231"
"","113.7850","24.0680","8160.9321"
"","113.8850","24.0885","8166.7676"
"","113.9850","24.1100","8160.1182"
"","114.0850","24.1306","8163.6489"
"","114.1850","24.1529","8162.0581"
"","114.2850","24.1733","8161.2422"
"","114.3850","24.1950","8162.1177"
"","114.4850","24.2154","8160.6128"
"","114.5850","24.2370","8162.6587"
"","114.6850","24.2586","8158.4297"
"","114.7850","24.2789","8162.4741"
"","114.8850","24.3006","8157.0649"
"","114.9850","24.3210","8160.2349"
"","115.0850","24.3432","8158.9990"
"","115.1850","24.3639","8156.3721"
"","115.2850","24.3851","8160.3350"
"","115.3850","24.4060","8156.4277"
"","115.4850","24.4272","8159.6025"
"","115.5850","24.4491","8155.4229"
"","115.6850","24.4695","8157.7158"
"","115.7850","24.4911","8154.9292"
"","115.8850","24.5117","8156.1162"
"","115.9850","24.5336","8156.1372"
"","116.0850","24.5546","8151.5811"
"","116.1850","24.5754","8157.5884"
"","116.2850","24.5966","8150.6992"
"","116.3850","24.6175","8154.1641"
"","116.4850","24.6397","8151.4902"
"","116.5850","24.6599","8151.6123"
"","116.6850","24.6816","8151.7563"
"","116.7850","24.7022","8151.5879"
"","116.8850","24.7239","8153.7412"
"","116.9850","24.7453","8148.5874"
"","117.0850","24.7660","8153.5732"
"","117.1850","24.7874","8148.2744"
"","117.2850","24.8078","8150.9800"
"","117.3850","24.8303","8148.2896"
"","117.4850","24.8505","8147.0708"
"","117.5850","24.8722","8149.5454"
"","117.6850","24.8928","8146.6719"
"","117.7850","24.9142","8149.7832"
"","117.8850","24.9358","8144.6162"
"","117.9850","24.9563","8147.6875"
"","118.0850","24.9780","8140.7793"
"","118.1850","24.9984","8136.3389"
"","118.2850","25.0202","8125.8350"
"","118.3850","25.0413","8116.2622"
"","118.4850","25.0626","8117.5371"
"","118.5850","25.0835","8109.9868"
"","118.6850","25.1044","8113.3887"
"","118.7850","25.1266","8105.5029"
"","118.8850","25.1465","8103.4443"
"","118.9850","25.1684","8099.8188"
"","119.0850","25.1889","8098.2349"
"","119.1850","25.2109","8099.6753"
"","119.2850","25.2321","8093.4346"
"","119.3850","25.2528","8099.2856"
"","119.4850","25.2740","8092.0742"
"","119.5850","25.2946","8093.7363"
"","119.6850","25.3172","8090.0601"
"","119.7850","25.3371","8086.5713"
"","119.8850","25.3592","8088.6128"
"","119.9850","25.3797","8084.9873"
"","120.0850","25.4013","8087.1338"
"","120.1850","25.4228","8077.3721"
"","120.2850","25.4432","8079.6807"
"","120.3850","25.4647","8069.3091"
"","120.4850","25.4852","8068.4854"
"","120.5850","25.5075","8062.8848"
"","120.6850","25.5278","8056.6758"
"","120.7850","25.5494","8060.1958"
"","120.8850","25.5701","8054.5381"
"","120.9850","25.5915","8058.9683"
"","121.0850","25.6133","8050.3926"
"","121.1850","25.6336","8050.8887"
"","121.2850","25.6553","8046.1084"
"","121.3850","25.6757","8043.4048"
"","121.4850","25.6978","8041.1128"
"","121.5850","25.7186","8033.1040"
"","121.6850","25.7397","8036.4419"
"","121.7850","25.7608","8028.2324"
"","121.8850","25.7819","8028.5005"
"","121.9850","25.8038","8021.8696"
"","122.0850","25.8239","8018.8745"
"","122.1850","25.8458","8014.4902"
"","122.2850","25.8664","8010.6279"
"","122.3850","25.8880","8008.4668"
"","122.4850","25.9094","7998.7007"
"","122.5850","25.9301","8001.1646"
"","122.6850","25.9515","7992.4985"
"","122.7850","25.9723","7991.8130"
"","122.8850","25.9945","7985.2690"
"","122.9850","26.0147","7978.9004"
"","123.0850","26.0362","7977.8867"
"","123.1850","26.0568","7970.2930"
"","123.2850","26.0785","7969.7803"
"","123.3850","26.0999","7957.1919"
"","123.4850","26.1205","7960.2988"
"","123.5850","26.1420","7947.5493"
"","123.6850","26.1625","7946.2358"
"","123.7850","26.1847","7940.3809"
"","123.8850","26.2054","7928.9482"
"","123.9850","26.2268","7930.2788"
"","124.0850","26.2476","7917.1733"
"","124.1850","26.2688","7916.8359"
"","124.2850","26.2905","7902.4976"
"","124.3850","26.3108","7901.1289"
"","124.4850","26.3328","7888.9326"
"","124.5850","26.3530","7884.7231"
"","124.6850","26.3751","7875.7031"
"","124.7850","26.3957","7862.6611"
"","124.8850","26.4170","7860.3359"
"","124.9850","26.4381","7842.3677"
"","125.0850","26.4591","7838.8779"
"","125.1850","26.4814","7821.4199"
"","125.2850","26.5015","7812.3823"
"","125.3850","26.5233","7798.1494"
"","125.4850","26.5437","7784.7490"
"","125.5850","26.5656","7772.3989"
"","125.6850","26.5868","7748.7358"
"","125.7850","26.6076","7740.3223"
"","125.8850","26.6285","7713.1333"
"","125.9850","26.6495","7697.6865"
"","126.0850","26.6717","7669.5747"
"","126.1850","26.6920","7643.6987"
"","126.2850","26.7135","7616.9438"
"","126.3850","26.7342","7583.3062"
"","126.4850","26.7558","7550.3813"
"","126.5850","26.7775","7504.8311"
"","126.6850","26.7978","7468.4614"
"","126.7850","26.8194","7411.8032"
"","126.8850","26.8400","7360.4136"
"","126.9850","26.8623","7289.7368"
"","127.0850","26.8826","7212.0220"
"","127.1850","26.9040","7107.6577"
"","127.2270","26.9130","6825.4136"
"","127.2300","26.9137","6465.0879"
"","127.2320","26.9141","6156.2803"
"","127.2340","26.9145","5808.6860"
"","127.2360","26.9150","5433.6147"
"","127.2380","26.9154","5041.0903"
"","127.2400","26.9158","4639.5508"
"","127.2420","26.9163","4236.1948"